Promise对象是JavaScript中用于处理异步操作的一种机制。它表示一个在未来某个时间点可能会产生某个值的对象，这个值可能是异步操作的结果，也可能是一个错误。

### 什么是Promise？

Promise有三种状态：
1. **Pending（待定）**: 初始状态，既不是成功（fulfilled），也不是失败（rejected）。
2. **Fulfilled（已完成）**: 意味着操作成功完成。
3. **Rejected（已失败）**: 意味着操作失败。

### 创建和返回Promise

当我们创建一个Promise对象时，通常会传递一个函数给它，这个函数有两个参数：`resolve` 和 `reject`。当异步操作成功时，我们调用`resolve`，当操作失败时，我们调用`reject`。

示例：

```javascript
function asyncOperation() {
  return new Promise((resolve, reject) => {
    setTimeout(() => {
      // 模拟异步操作
      const success = true; // 或者 false 来模拟失败

      if (success) {
        resolve('Operation succeeded');
      } else {
        reject('Operation failed');
      }
    }, 2000);
  });
}
```

在这个例子中，`asyncOperation`函数返回一个Promise对象。在这个Promise内部，我们使用`setTimeout`来模拟一个异步操作，该操作在2秒钟后完成。如果`success`为`true`，我们调用`resolve`来表示操作成功；如果`success`为`false`，我们调用`reject`来表示操作失败。

### 使用返回的Promise

当一个函数返回一个Promise时，我们可以使用`.then`和`.catch`方法来处理操作成功或失败的结果。

```javascript
asyncOperation()
  .then(result => {
    console.log(result); // 输出: Operation succeeded
  })
  .catch(error => {
    console.error(error); // 输出: Operation failed（如果操作失败）
  });
```

### 使用 async/await 处理返回的Promise

在ES8中，我们可以使用`async`和`await`来处理返回的Promise，使代码更简洁、更易读。

```javascript
async function handleAsyncOperation() {
  try {
    const result = await asyncOperation();
    console.log(result); // 输出: Operation succeeded
  } catch (error) {
    console.error(error); // 输出: Operation failed（如果操作失败）
  }
}

handleAsyncOperation();
```

在这个例子中，`async`关键字使`handleAsyncOperation`成为一个异步函数，并且我们可以使用`await`来等待`asyncOperation`返回的Promise完成。如果Promise成功，我们得到结果并输出；如果Promise失败，我们捕获错误并输出。

总结起来，当我们说一个函数“返回一个Promise”时，意味着这个函数会异步地进行一些操作，并且会在操作完成或失败后，通过Promise对象通知调用者结果。
理解 `.then` 和 `.catch` 的使用时机有助于更好地处理 JavaScript 中的异步操作。

### `.then` 方法

`.then` 方法用于处理 Promise 成功完成时的结果。它接受两个参数：第一个是处理成功结果的回调函数，第二个是可选的处理错误的回调函数。

```javascript
let promise = new Promise((resolve, reject) => {
  setTimeout(() => {
    resolve('Success');
  }, 1000);
});

promise.then(result => {
  console.log(result); // 输出: Success
});
```

在这个例子中，`resolve('Success')` 被调用后，Promise 的状态变为 `fulfilled`，并且传递给 `.then` 方法的回调函数将被执行，输出 'Success'。

### `.catch` 方法

`.catch` 方法用于处理 Promise 失败时的错误。它只接受一个参数，即处理错误的回调函数。

```javascript
let promise = new Promise((resolve, reject) => {
  setTimeout(() => {
    reject('Error');
  }, 1000);
});

promise.catch(error => {
  console.error(error); // 输出: Error
});
```

在这个例子中，`reject('Error')` 被调用后，Promise 的状态变为 `rejected`，并且传递给 `.catch` 方法的回调函数将被执行，输出 'Error'。

### 结合使用 `.then` 和 `.catch`

通常情况下，我们会将 `.then` 和 `.catch` 结合使用，以处理成功和失败的两种情况。

```javascript
let promise = new Promise((resolve, reject) => {
  setTimeout(() => {
    const success = true; // 模拟成功或失败
    if (success) {
      resolve('Success');
    } else {
      reject('Error');
    }
  }, 1000);
});

promise
  .then(result => {
    console.log(result); // 如果成功，输出: Success
  })
  .catch(error => {
    console.error(error); // 如果失败，输出: Error
  });
```

在这个例子中，`promise` 对象可能会成功也可能会失败。我们通过 `.then` 处理成功的情况，通过 `.catch` 处理失败的情况。

### 使用 async/await 和 try/catch

使用 `async/await` 可以让代码更简洁。在使用 `async/await` 时，我们可以通过 `try/catch` 语句来处理成功和失败的情况。

```javascript
async function asyncCall() {
  try {
    let result = await promise;
    console.log(result); // 如果成功，输出: Success
  } catch (error) {
    console.error(error); // 如果失败，输出: Error
  }
}

asyncCall();
```

在这个例子中，`await promise` 等待 `promise` 完成，如果成功，结果会赋值给 `result` 并输出；如果失败，会抛出错误并被 `catch` 块捕获。

总结起来：

- 使用 `.then` 处理 Promise 成功完成的结果。
- 使用 `.catch` 处理 Promise 失败时的错误。
- 结合 `.then` 和 `.catch` 处理成功和失败的情况。
- 使用 `async/await` 和 `try/catch` 让代码更简洁。